<?xml version="1.0" encoding="UTF-8"?>
<testng-results ignored="2" total="6" passed="1" failed="2" skipped="1">
  <reporter-output>
  </reporter-output>
  <suite started-at="2021-10-02T13:49:15Z" name="Default suite" finished-at="2021-10-02T13:49:17Z" duration-ms="2221">
    <groups>
    </groups>
    <test started-at="2021-10-02T13:49:15Z" name="Default test" finished-at="2021-10-02T13:49:17Z" duration-ms="2221">
      <class name="com.sk.testngsamples.OtherConcepts">
        <test-method signature="bTest()[pri:0, instance:com.sk.testngsamples.OtherConcepts@610f7aa]" started-at="2021-10-02T13:49:15Z" name="bTest" finished-at="2021-10-02T13:49:15Z" duration-ms="12" status="SKIP">
          <exception class="org.testng.SkipException">
            <message>
              <![CDATA[Skipping OC]]>
            </message>
            <full-stacktrace>
              <![CDATA[org.testng.SkipException: Skipping OC
at com.sk.testngsamples.OtherConcepts.bTest(OtherConcepts.java:32)
at java.base/jdk.internal.reflect.NativeMethodAccessorImpl.invoke0(Native Method)
at java.base/jdk.internal.reflect.NativeMethodAccessorImpl.invoke(NativeMethodAccessorImpl.java:62)
at java.base/jdk.internal.reflect.DelegatingMethodAccessorImpl.invoke(DelegatingMethodAccessorImpl.java:43)
at java.base/java.lang.reflect.Method.invoke(Method.java:566)
at org.testng.internal.MethodInvocationHelper.invokeMethod(MethodInvocationHelper.java:124)
at org.testng.internal.Invoker.invokeMethod(Invoker.java:583)
at org.testng.internal.Invoker.invokeTestMethod(Invoker.java:719)
at org.testng.internal.Invoker.invokeTestMethods(Invoker.java:989)
at org.testng.internal.TestMethodWorker.invokeTestMethods(TestMethodWorker.java:125)
at org.testng.internal.TestMethodWorker.run(TestMethodWorker.java:109)
at org.testng.TestRunner.privateRun(TestRunner.java:648)
at org.testng.TestRunner.run(TestRunner.java:505)
at org.testng.SuiteRunner.runTest(SuiteRunner.java:455)
at org.testng.SuiteRunner.runSequentially(SuiteRunner.java:450)
at org.testng.SuiteRunner.privateRun(SuiteRunner.java:415)
at org.testng.SuiteRunner.run(SuiteRunner.java:364)
at org.testng.SuiteRunnerWorker.runSuite(SuiteRunnerWorker.java:52)
at org.testng.SuiteRunnerWorker.run(SuiteRunnerWorker.java:84)
at org.testng.TestNG.runSuitesSequentially(TestNG.java:1208)
at org.testng.TestNG.runSuitesLocally(TestNG.java:1137)
at org.testng.TestNG.runSuites(TestNG.java:1049)
at org.testng.TestNG.run(TestNG.java:1017)
at org.testng.remote.AbstractRemoteTestNG.run(AbstractRemoteTestNG.java:114)
at org.testng.remote.RemoteTestNG.initAndRun(RemoteTestNG.java:251)
at org.testng.remote.RemoteTestNG.main(RemoteTestNG.java:77)
]]>
            </full-stacktrace>
          </exception> <!-- org.testng.SkipException -->
          <reporter-output>
          </reporter-output>
        </test-method> <!-- bTest -->
        <test-method signature="cTest()[pri:0, instance:com.sk.testngsamples.OtherConcepts@610f7aa]" started-at="2021-10-02T13:49:15Z" name="cTest" finished-at="2021-10-02T13:49:17Z" duration-ms="2138" status="FAIL">
          <exception class="org.testng.internal.thread.ThreadTimeoutException">
            <message>
              <![CDATA[Method com.sk.testngsamples.OtherConcepts.cTest() didn't finish within the time-out 2000]]>
            </message>
            <full-stacktrace>
              <![CDATA[org.testng.internal.thread.ThreadTimeoutException: Method com.sk.testngsamples.OtherConcepts.cTest() didn't finish within the time-out 2000
at java.base@11/java.lang.invoke.MethodType.insertParameterTypes(MethodType.java:401)
at java.base@11/java.lang.invoke.VarHandle$AccessDescriptor.<init>(VarHandle.java:1853)
at java.base@11/java.lang.invoke.MethodHandleNatives.varHandleOperationLinkerMethod(MethodHandleNatives.java:518)
at java.base@11/java.lang.invoke.MethodHandleNatives.linkMethodImpl(MethodHandleNatives.java:462)
at java.base@11/java.lang.invoke.MethodHandleNatives.linkMethod(MethodHandleNatives.java:450)
at java.base@11/java.util.concurrent.FutureTask.setException(FutureTask.java:247)
at java.base@11/java.util.concurrent.FutureTask.run(FutureTask.java:269)
at java.base@11/java.util.concurrent.ThreadPoolExecutor.runWorker(ThreadPoolExecutor.java:1128)
at java.base@11/java.util.concurrent.ThreadPoolExecutor$Worker.run(ThreadPoolExecutor.java:628)
at java.base@11/java.lang.Thread.run(Thread.java:834)
]]>
            </full-stacktrace>
          </exception> <!-- org.testng.internal.thread.ThreadTimeoutException -->
          <reporter-output>
          </reporter-output>
        </test-method> <!-- cTest -->
        <test-method signature="dTest()[pri:0, instance:com.sk.testngsamples.OtherConcepts@610f7aa]" started-at="2021-10-02T13:49:17Z" name="dTest" finished-at="2021-10-02T13:49:17Z" duration-ms="4" status="PASS">
          <exception class="java.lang.ArithmeticException">
            <message>
              <![CDATA[/ by zero]]>
            </message>
            <full-stacktrace>
              <![CDATA[java.lang.ArithmeticException: / by zero
at com.sk.testngsamples.OtherConcepts.dTest(OtherConcepts.java:47)
at java.base/jdk.internal.reflect.NativeMethodAccessorImpl.invoke0(Native Method)
at java.base/jdk.internal.reflect.NativeMethodAccessorImpl.invoke(NativeMethodAccessorImpl.java:62)
at java.base/jdk.internal.reflect.DelegatingMethodAccessorImpl.invoke(DelegatingMethodAccessorImpl.java:43)
at java.base/java.lang.reflect.Method.invoke(Method.java:566)
at org.testng.internal.MethodInvocationHelper.invokeMethod(MethodInvocationHelper.java:124)
at org.testng.internal.Invoker.invokeMethod(Invoker.java:583)
at org.testng.internal.Invoker.invokeTestMethod(Invoker.java:719)
at org.testng.internal.Invoker.invokeTestMethods(Invoker.java:989)
at org.testng.internal.TestMethodWorker.invokeTestMethods(TestMethodWorker.java:125)
at org.testng.internal.TestMethodWorker.run(TestMethodWorker.java:109)
at org.testng.TestRunner.privateRun(TestRunner.java:648)
at org.testng.TestRunner.run(TestRunner.java:505)
at org.testng.SuiteRunner.runTest(SuiteRunner.java:455)
at org.testng.SuiteRunner.runSequentially(SuiteRunner.java:450)
at org.testng.SuiteRunner.privateRun(SuiteRunner.java:415)
at org.testng.SuiteRunner.run(SuiteRunner.java:364)
at org.testng.SuiteRunnerWorker.runSuite(SuiteRunnerWorker.java:52)
at org.testng.SuiteRunnerWorker.run(SuiteRunnerWorker.java:84)
at org.testng.TestNG.runSuitesSequentially(TestNG.java:1208)
at org.testng.TestNG.runSuitesLocally(TestNG.java:1137)
at org.testng.TestNG.runSuites(TestNG.java:1049)
at org.testng.TestNG.run(TestNG.java:1017)
at org.testng.remote.AbstractRemoteTestNG.run(AbstractRemoteTestNG.java:114)
at org.testng.remote.RemoteTestNG.initAndRun(RemoteTestNG.java:251)
at org.testng.remote.RemoteTestNG.main(RemoteTestNG.java:77)
]]>
            </full-stacktrace>
          </exception> <!-- java.lang.ArithmeticException -->
          <reporter-output>
          </reporter-output>
        </test-method> <!-- dTest -->
        <test-method signature="eTest()[pri:0, instance:com.sk.testngsamples.OtherConcepts@610f7aa]" started-at="2021-10-02T13:49:17Z" name="eTest" finished-at="2021-10-02T13:49:17Z" duration-ms="5" status="FAIL">
          <exception class="org.testng.TestException">
            <message>
              <![CDATA[
Expected exception of type class java.lang.ArithmeticException but got java.lang.ArrayIndexOutOfBoundsException: Index 5 out of bounds for length 5]]>
            </message>
            <full-stacktrace>
              <![CDATA[org.testng.TestException: 
Expected exception of type class java.lang.ArithmeticException but got java.lang.ArrayIndexOutOfBoundsException: Index 5 out of bounds for length 5
at org.testng.internal.ExpectedExceptionsHolder.wrongException(ExpectedExceptionsHolder.java:68)
at org.testng.internal.Invoker.considerExceptions(Invoker.java:1130)
at org.testng.internal.Invoker.invokeMethod(Invoker.java:615)
at org.testng.internal.Invoker.invokeTestMethod(Invoker.java:719)
at org.testng.internal.Invoker.invokeTestMethods(Invoker.java:989)
at org.testng.internal.TestMethodWorker.invokeTestMethods(TestMethodWorker.java:125)
at org.testng.internal.TestMethodWorker.run(TestMethodWorker.java:109)
at org.testng.TestRunner.privateRun(TestRunner.java:648)
at org.testng.TestRunner.run(TestRunner.java:505)
at org.testng.SuiteRunner.runTest(SuiteRunner.java:455)
at org.testng.SuiteRunner.runSequentially(SuiteRunner.java:450)
at org.testng.SuiteRunner.privateRun(SuiteRunner.java:415)
at org.testng.SuiteRunner.run(SuiteRunner.java:364)
at org.testng.SuiteRunnerWorker.runSuite(SuiteRunnerWorker.java:52)
at org.testng.SuiteRunnerWorker.run(SuiteRunnerWorker.java:84)
at org.testng.TestNG.runSuitesSequentially(TestNG.java:1208)
at org.testng.TestNG.runSuitesLocally(TestNG.java:1137)
at org.testng.TestNG.runSuites(TestNG.java:1049)
at org.testng.TestNG.run(TestNG.java:1017)
at org.testng.remote.AbstractRemoteTestNG.run(AbstractRemoteTestNG.java:114)
at org.testng.remote.RemoteTestNG.initAndRun(RemoteTestNG.java:251)
at org.testng.remote.RemoteTestNG.main(RemoteTestNG.java:77)
Caused by: java.lang.ArrayIndexOutOfBoundsException: Index 5 out of bounds for length 5
at com.sk.testngsamples.OtherConcepts.eTest(OtherConcepts.java:55)
at java.base/jdk.internal.reflect.NativeMethodAccessorImpl.invoke0(Native Method)
at java.base/jdk.internal.reflect.NativeMethodAccessorImpl.invoke(NativeMethodAccessorImpl.java:62)
at java.base/jdk.internal.reflect.DelegatingMethodAccessorImpl.invoke(DelegatingMethodAccessorImpl.java:43)
at java.base/java.lang.reflect.Method.invoke(Method.java:566)
at org.testng.internal.MethodInvocationHelper.invokeMethod(MethodInvocationHelper.java:124)
at org.testng.internal.Invoker.invokeMethod(Invoker.java:583)
... 19 more
]]>
            </full-stacktrace>
          </exception> <!-- org.testng.TestException -->
          <reporter-output>
          </reporter-output>
        </test-method> <!-- eTest -->
      </class> <!-- com.sk.testngsamples.OtherConcepts -->
    </test> <!-- Default test -->
  </suite> <!-- Default suite -->
</testng-results>
